INFO:django:GET / AnonymousUser
ERROR:django.request:Internal Server Error: /
Traceback (most recent call last):
  File "C:\Users\Abdullaah.DESKTOP-LH4UKJQ\Desktop\alx-backend-python\Django-Middleware-0x03\.venv\lib\site-packages\django\core\handlers\exception.py", line 55, in inner
    response = get_response(request)
  File "C:\Users\Abdullaah.DESKTOP-LH4UKJQ\Desktop\alx-backend-python\Django-Middleware-0x03\chats\middleware.py", line 24, in __call__
    current_hour = time.localtime().tm_hour
AttributeError: type object 'datetime.time' has no attribute 'localtime'
INFO:django:GET /favicon.ico AnonymousUser
ERROR:django.request:Internal Server Error: /favicon.ico
Traceback (most recent call last):
  File "C:\Users\Abdullaah.DESKTOP-LH4UKJQ\Desktop\alx-backend-python\Django-Middleware-0x03\.venv\lib\site-packages\django\core\handlers\exception.py", line 55, in inner
    response = get_response(request)
  File "C:\Users\Abdullaah.DESKTOP-LH4UKJQ\Desktop\alx-backend-python\Django-Middleware-0x03\chats\middleware.py", line 24, in __call__
    current_hour = time.localtime().tm_hour
AttributeError: type object 'datetime.time' has no attribute 'localtime'
